Workbook

Sheet BASE_CALCULO
A1: CALCULO DE FRETE POR TAMANHO DE PEÇA
A3: KILOMETRAGEM -> | B3: 1
A5: Separador de Água e Óleo 12.000 l
A8: VALOR DO FRETE -> | B8: =VLOOKUP(A5,CADASTRO_PRODUTO!C:E,3,FALSE) -> 1.9352941
A11: OCUPAÇÃO DO CAMINHÃO | B11: =VLOOKUP(A5,CADASTRO_PRODUTO!C3:D339,2,FALSE) -> 2.35
A14: OCUPAÇÃO DO CAMINHÃO | B14: =((B11*100/8.5)%) -> 0.27647059

Sheet D
D1: CALCULO DE FRETE POR TAMANHO DE PEÇA
A2: PEÇAS HORIZONTAIS USAR LARGURA | D2: KILOMETRAGEM -> | F2: 1000
A4: PEÇAS VERTICAIS USAR ALTURA | D4: TAMANHO DA PEÇA -> | F4: 2.5
A6: TC ABAIXO DE 10.000L USAR LARGURA MAIOR
D7: VALOR DO FRETE -> | F7: =F2*E11/E12*F4 -> 2058.8235
A9: FOSSAS POLI USAR A ALTURA
A11: PEÇAS VERTICAIS USAR ALTURA | D11: VALOR KM | E11: 7
D12: TAMANHO CAMINHAO | E12: 8.5

Sheet CADASTRO_PRODUTO
C1: Adensador de Lodo - Modelo Cilíndrico - 1.000 l | D1: 1.69 | E1: =IF(D1="","",SUM(BASE_CALCULO!$B$3*$B$2/$B$3*D1)) -> 1.3917647
A2: VALOR KM | B2: 7 | C2: Adensador de Lodo - Modelo Cilíndrico - 1.000 l | D2: 0.91 | E2: =IF(D2="","",SUM(BASE_CALCULO!$B$3*$B$2/$B$3*D2)) -> 0.74941176
A3: TAMANHO CAMINHAO | B3: 8.5 | C3: Adensador de Lodo - Modelo Cilíndrico - 10.700 l | D3: 3.25 | E3: =IF(D3="","",SUM(BASE_CALCULO!$B$3*$B$2/$B$3*D3)) -> 2.6764706
C4: Adensador de Lodo - Modelo Cilíndrico - 10.700 l | D4: 1.8 | E4: =IF(D4="","",SUM(BASE_CALCULO!$B$3*$B$2/$B$3*D4)) -> 1.4823529
C5: Adensador de Lodo - Modelo Cilíndrico - 2.650 l | D5: 1.93 | E5: =IF(D5="","",SUM(BASE_CALCULO!$B$3*$B$2/$B$3*D5)) -> 1.5894118
C6: Adensador de Lodo - Modelo Cilíndrico - 2.650 l | D6: 1.6 | E6: =IF(D6="","",SUM(BASE_CALCULO!$B$3*$B$2/$B$3*D6)) -> 1.3176471
C7: Adensador de Lodo - Modelo Cilíndrico - 21.300 l | D7: 4.25 | E7: =IF(D7="","",SUM(BASE_CALCULO!$B$3*$B$2/$B$3*D7)) -> 3.5
C8: Adensador de Lodo - Modelo Cilíndrico - 21.300 l | D8: 2.45 | E8: =IF(D8="","",SUM(BASE_CALCULO!$B$3*$B$2/$B$3*D8)) -> 2.0176471
C9: Adensador de Lodo - Modelo Cilíndrico - 5.300 l | D9: 2.35 | E9: =IF(D9="","",SUM(BASE_CALCULO!$B$3*$B$2/$B$3*D9)) -> 1.9352941
C10: Adensador de Lodo - Modelo Cilíndrico - 5.300 l | D10: 1.8 | E10: =IF(D10="","",SUM(BASE_CALCULO!$B$3*$B$2/$B$3*D10)) -> 1.4823529
C11: Adensador de Lodo - Modelo Tronco - Cônico - 10000 l | D11: 2.72 | E11: =IF(D11="","",SUM(BASE_CALCULO!$B$3*$B$2/$B$3*D11)) -> 2.24
C12: Adensador de Lodo - Modelo Tronco - Cônico - 10000 l | D12: 2.72 | E12: =IF(D12="","",SUM(BASE_CALCULO!$B$3*$B$2/$B$3*D12)) -> 2.24
C13: Adensador de Lodo - Modelo Tronco - Cônico - 15000 l | D13: 2.93 | E13: =IF(D13="","",SUM(BASE_CALCULO!$B$3*$B$2/$B$3*D13)) -> 2.4129412
C14: Adensador de Lodo - Modelo Tronco - Cônico - 15000 l | D14: 2.93 | E14: =IF(D14="","",SUM(BASE_CALCULO!$B$3*$B$2/$B$3*D14)) -> 2.4129412
C15: Adensador de Lodo - Modelo Tronco - Cônico - 20000 l | D15: 3.65 | E15: =IF(D15="","",SUM(BASE_CALCULO!$B$3*$B$2/$B$3*D15)) -> 3.0058824
... C156: Fossa em Polietileno - 20.000 l | D156: 2.95 | E156: =IF(D156="","",SUM(BASE_CALCULO!$B$3*$B$2/$B$3*D156)) -> 2.4294118
C157: PRODUTOS | D157: MEDIDA | E157: VALOR KM
C158: Reator Tucunaré 16.000 | D158: 3.25 | E158: =IF(D158="","",SUM(BASE_CALCULO!$B$3*$B$2/$B$3*D158)) -> 2.6764706
C159: Reator Tucunaré 32.000 | D159: 4.25 | E159: =IF(D159="","",SUM(BASE_CALCULO!$B$3*$B$2/$B$3*D159)) -> 3.5
C160: Reator Tucunaré 4.000 | D160: 1.93 | E160: =IF(D160="","",SUM(BASE_CALCULO!$B$3*$B$2/$B$3*D160)) -> 1.5894118
C161: Reator Tucunaré 8.000 | D161: 2.35 | E161: =IF(D161="","",SUM(BASE_CALCULO!$B$3*$B$2/$B$3*D161)) -> 1.9352941
C162: Reator UASB 10.000 l | D162: 2.72 | E162: =IF(D162="","",SUM(BASE_CALCULO!$B$3*$B$2/$B$3*D162)) -> 2.24
C163: Reator UASB 12.000 l | D163: 2.43 | E163: =IF(D163="","",SUM(BASE_CALCULO!$B$3*$B$2/$B$3*D163)) -> 2.0011765
C164: Reator UASB 15.000 l | D164: 2.93 | E164: =IF(D164="","",SUM(BASE_CALCULO!$B$3*$B$2/$B$3*D164)) -> 2.4129412
C165: Reator UASB 2.000 l | D165: 1.12 | E165: =IF(D165="","",SUM(BASE_CALCULO!$B$3*$B$2/$B$3*D165)) -> 0.92235294
C166: Reator UASB 20.000 l | D166: 3.65 | E166: =IF(D166="","",SUM(BASE_CALCULO!$B$3*$B$2/$B$3*D166)) -> 3.0058824
C167: Reator UASB 25.000 l | D167: 4.4 | E167: =IF(D167="","",SUM(BASE_CALCULO!$B$3*$B$2/$B$3*D167)) -> 3.6235294
C168: Reator UASB 3.000 l | D168: 1.71 | E168: =IF(D168="","",SUM(BASE_CALCULO!$B$3*$B$2/$B$3*D168)) -> 1.4082353
C169: Reator UASB 5.000 l | D169: 1.75 | E169: =IF(D169="","",SUM(BASE_CALCULO!$B$3*$B$2/$B$3*D169)) -> 1.4411765
... C322: Tanques Misturadores 1.000 l | D322: 1.4 | E322: =IF(D322="","",SUM(BASE_CALCULO!$B$3*$B$2/$B$3*D322)) -> 1.1529412
C323: Tanques Misturadores 1.000 l | D323: 1.1 | E323: =IF(D323="","",SUM(BASE_CALCULO!$B$3*$B$2/$B$3*D323)) -> 0.90588235 | F323: m³
C324: Tanques Misturadores 2.500 l | D324: 1.6 | E324: =IF(D324="","",SUM(BASE_CALCULO!$B$3*$B$2/$B$3*D324)) -> 1.3176471 | F324: m³
C325: Tanques Misturadores 2.500 l | D325: 1.1 | E325: =IF(D325="","",SUM(BASE_CALCULO!$B$3*$B$2/$B$3*D325)) -> 0.90588235 | F325: m³
C326: Tanques Misturadores 5.500 l | D326: 1.9 | E326: =IF(D326="","",SUM(BASE_CALCULO!$B$3*$B$2/$B$3*D326)) -> 1.5647059 | F326: m³
C327: Tanques Misturadores 5.500 l | D327: 1.45 | E327: =IF(D327="","",SUM(BASE_CALCULO!$B$3*$B$2/$B$3*D327)) -> 1.1941176 | F327: m³
C328: Tanques para Combustivel - 10.000 l | D328: 5.2 | E328: =IF(D328="","",SUM(BASE_CALCULO!$B$3*$B$2/$B$3*D328)) -> 4.2823529 | F328: m³
C329: Tanques para Combustivel - 15.000 l | D329: 3.85 | E329: =IF(D329="","",SUM(BASE_CALCULO!$B$3*$B$2/$B$3*D329)) -> 3.1705882
C330: Tanques para Combustivel - 2.500 l | D330: 1.7 | E330: =IF(D330="","",SUM(BASE_CALCULO!$B$3*$B$2/$B$3*D330)) -> 1.4
C331: Tanques para Combustivel - 20.000 l | D331: 4.85 | E331: =IF(D331="","",SUM(BASE_CALCULO!$B$3*$B$2/$B$3*D331)) -> 3.9941176
C332: Tanques para Combustivel - 25.000 l | D332: 5.85 | E332: =IF(D332="","",SUM(BASE_CALCULO!$B$3*$B$2/$B$3*D332)) -> 4.8176471
...
